Timestamp: 1755266387.7161787
Error: A very unexpected error
Traceback (most recent call last):
  File "/workspace/boysnoise/app.py", line 77, in synthesize_speech
    process = subprocess.run(command, check=True, capture_output=True, text=True, encoding='utf-8', timeout=120)
              ^^^^^^^^^^^^^^^^^^^^^^^^^^^^^^^^^^^^^^^^^^^^^^^^^^^^^^^^^^^^^^^^^^^^^^^^^^^^^^^^^^^^^^^^^^^^^^^^^^
  File "/home/gitpod/.pyenv/versions/3.11.9/lib/python3.11/unittest/mock.py", line 1124, in __call__
    return self._mock_call(*args, **kwargs)
           ^^^^^^^^^^^^^^^^^^^^^^^^^^^^^^^^
  File "/home/gitpod/.pyenv/versions/3.11.9/lib/python3.11/unittest/mock.py", line 1128, in _mock_call
    return self._execute_mock_call(*args, **kwargs)
           ^^^^^^^^^^^^^^^^^^^^^^^^^^^^^^^^^^^^^^^^
  File "/home/gitpod/.pyenv/versions/3.11.9/lib/python3.11/unittest/mock.py", line 1183, in _execute_mock_call
    raise effect
Exception: A very unexpected error
--- END OF ERROR ---